#VRML_SIM R2023b utf8

EXTERNPROTO "https://raw.githubusercontent.com/cyberbotics/webots/R2023b/projects/objects/backgrounds/protos/TexturedBackground.proto"
EXTERNPROTO "https://raw.githubusercontent.com/cyberbotics/webots/R2023b/projects/objects/backgrounds/protos/TexturedBackgroundLight.proto"
EXTERNPROTO "https://raw.githubusercontent.com/cyberbotics/webots/R2023b/projects/objects/floors/protos/RectangleArena.proto"
EXTERNPROTO "https://raw.githubusercontent.com/cyberbotics/webots/R2023b/projects/robots/universal_robots/protos/UR5e.proto"
EXTERNPROTO "https://raw.githubusercontent.com/cyberbotics/webots/R2023b/projects/objects/tables/protos/Table.proto"

WorldInfo {
  title "CSCI/ECEN 3302 - Lab: Gradient Descent IK Block Stacking"
  info [
    "University of Colorado Boulder"
    "Introduction to Robotics"
  ]
  basicTimeStep 16
  contactProperties [
    ContactProperties {
      material1 "gripper_pad"
      material2 "block"
      coulombFriction [0.9]
    }
  ]
}

Viewpoint {
  orientation -0.27 0.65 0.71 0.95
  position -1.8 -2.2 2.4
}

TexturedBackground {
}

TexturedBackgroundLight {
}

RectangleArena {
  floorSize 3 3
  floorTileSize 0.5 0.5
  wallHeight 0.05
}

Table {
  translation 0.4 0 0
  name "work_table"
  size 1.2 0.8 0.74
  feetSize 0.05 0.05
  legAppearance PBRAppearance {
    baseColor 0.6 0.6 0.6
    roughness 0.8
  }
  trayAppearance PBRAppearance {
    baseColor 0.85 0.85 0.85
    roughness 0.3
  }
}

UR5e {
  translation 0 0 0.74
  rotation 0 0 1 1.5708
  name "ur5e"
  controller "block_stacker"
  controllerArgs []
  selfCollision FALSE
  toolSlot [
    Solid {
      translation 0 0 0.02
      children [
        Shape {
          appearance PBRAppearance {
            baseColor 0.2 0.2 0.2
            roughness 0.5
            metalness 0.7
          }
          geometry Box {
            size 0.08 0.04 0.04
          }
        }
        HingeJoint {
          jointParameters HingeJointParameters {
            position 0
            axis 0 0 1
            anchor 0.03 0 -0.02
          }
          device [
            RotationalMotor {
              name "finger_left"
              maxVelocity 1.0
              minPosition -0.05
              maxPosition 0.0
              maxTorque 5.0
            }
          ]
          endPoint Solid {
            translation 0.03 0 -0.05
            children [
              Shape {
                appearance PBRAppearance {
                  baseColor 0.3 0.3 0.3
                  roughness 0.6
                  metalness 0.5
                }
                geometry Box {
                  size 0.012 0.03 0.06
                }
              }
              Solid {
                translation -0.008 0 -0.01
                children [
                  Shape {
                    appearance PBRAppearance {
                      baseColor 0.1 0.1 0.1
                      roughness 0.9
                    }
                    geometry Box {
                      size 0.004 0.025 0.04
                    }
                  }
                ]
                name "left_pad"
                contactMaterial "gripper_pad"
                boundingObject Box {
                  size 0.004 0.025 0.04
                }
                physics Physics {
                  density -1
                  mass 0.01
                }
              }
            ]
            name "finger_left"
            boundingObject Box {
              size 0.012 0.03 0.06
            }
            physics Physics {
              density -1
              mass 0.05
            }
          }
        }
        HingeJoint {
          jointParameters HingeJointParameters {
            position 0
            axis 0 0 1
            anchor -0.03 0 -0.02
          }
          device [
            RotationalMotor {
              name "finger_right"
              maxVelocity 1.0
              minPosition 0.0
              maxPosition 0.05
              maxTorque 5.0
            }
          ]
          endPoint Solid {
            translation -0.03 0 -0.05
            children [
              Shape {
                appearance PBRAppearance {
                  baseColor 0.3 0.3 0.3
                  roughness 0.6
                  metalness 0.5
                }
                geometry Box {
                  size 0.012 0.03 0.06
                }
              }
              Solid {
                translation 0.008 0 -0.01
                children [
                  Shape {
                    appearance PBRAppearance {
                      baseColor 0.1 0.1 0.1
                      roughness 0.9
                    }
                    geometry Box {
                      size 0.004 0.025 0.04
                    }
                  }
                ]
                name "right_pad"
                contactMaterial "gripper_pad"
                boundingObject Box {
                  size 0.004 0.025 0.04
                }
                physics Physics {
                  density -1
                  mass 0.01
                }
              }
            ]
            name "finger_right"
            boundingObject Box {
              size 0.012 0.03 0.06
            }
            physics Physics {
              density -1
              mass 0.05
            }
          }
        }
      ]
      name "gripper_base"
      boundingObject Box {
        size 0.08 0.04 0.04
      }
      physics Physics {
        density -1
        mass 0.2
      }
    }
  ]
}

DEF BLOCK_A Solid {
  translation 0.35 -0.2 0.79
  rotation 0 0 1 0.15
  children [
    Shape {
      appearance PBRAppearance {
        baseColor 0.85 0.15 0.15
        roughness 0.4
      }
      geometry Box {
        size 0.05 0.05 0.05
      }
    }
  ]
  name "block_A"
  contactMaterial "block"
  boundingObject Box {
    size 0.05 0.05 0.05
  }
  physics Physics {
    density -1
    mass 0.1
  }
}

DEF BLOCK_B Solid {
  translation 0.5 -0.25 0.79
  rotation 0 0 1 -0.3
  children [
    Shape {
      appearance PBRAppearance {
        baseColor 0.15 0.75 0.2
        roughness 0.4
      }
      geometry Box {
        size 0.05 0.05 0.05
      }
    }
  ]
  name "block_B"
  contactMaterial "block"
  boundingObject Box {
    size 0.05 0.05 0.05
  }
  physics Physics {
    density -1
    mass 0.1
  }
}

DEF BLOCK_C Solid {
  translation 0.6 -0.12 0.79
  rotation 0 0 1 0.45
  children [
    Shape {
      appearance PBRAppearance {
        baseColor 0.15 0.25 0.85
        roughness 0.4
      }
      geometry Box {
        size 0.05 0.05 0.05
      }
    }
  ]
  name "block_C"
  contactMaterial "block"
  boundingObject Box {
    size 0.05 0.05 0.05
  }
  physics Physics {
    density -1
    mass 0.1
  }
}

DEF TARGET_ZONE Solid {
  translation 0.35 0.2 0.74
  children [
    Shape {
      appearance PBRAppearance {
        baseColor 1.0 0.85 0.0
        roughness 0.9
        transparency 0.6
      }
      geometry Cylinder {
        height 0.002
        radius 0.06
      }
    }
  ]
  name "target_zone"
}

DEF OBSTACLE Solid {
  translation 0.4 0.0 0.79
  children [
    Shape {
      appearance PBRAppearance {
        baseColor 0.4 0.4 0.4
        roughness 0.5
        metalness 0.2
      }
      geometry Box {
        size 0.08 0.15 0.08
      }
    }
  ]
  name "obstacle"
  boundingObject Box {
    size 0.08 0.15 0.08
  }
  physics Physics {
    density -1
    mass 2.0
  }
}
